Workbook
Name Ccy: Inputs!$C$7
Name circ: Inputs!$C$10
Name CoName: Inputs!$C$4
Name g: Presentation!$R$17
Name IQ_CH: 110000
Name IQ_CQ: 5000
Name IQ_CY: 10000
Name IQ_DAILY: 500000
Name IQ_FH: 100000
Name IQ_FQ: 500
Name IQ_FY: 1000
Name IQ_LTM: 2000
Name IQ_MONTH: 15000
Name IQ_NTM: 6000
Name IQ_WEEK: 50000
Name IQ_YTD: 3000
Name OpCase: [1]DCF!$E$98
Name ScenarioCAPEX: Assumptions!$P$3
Name ScenarioCOGS: Assumptions!$L$3
Name ScenarioREV: Assumptions!$D$3
Name TTS: #REF!
Name Units: Inputs!$C$8
Name wacc: 'DCF Model'!$C$27

Sheet Inputs
A1: =CoName -> Alphabet Inc.
A2: Advanced DCF + COMPS + SOTP Analysis
B4: Company name | C4: Alphabet Inc. | E4: Diluted s/o | F4: =28196/2.31 -> 12206.061
B5: Current Stock Price | C5: {=_FV(A14,"Price")} -> 253.3 | E5: Mkt Cap | F5: =F4*C5 -> 3091795.2
B6: Latest BS date | C6: 45690 | E6: Cash | F6: =21036+74112 -> 95148
B7: Currency | C7: USD | E7: Debt | F7: =23607 -> 23607
B8: Units | C8: m | E8: EV | F8: =F5-F6+F7 -> 3020254.2
B9: Analyst name | C9: Alan Chen
B10: Circular switch | C10: 0
B11: TURN THIS ON AFTER TURNING ON ITERATIONS, NOT BEFORE
A13: Other temp stuff
A14: #VALUE!
F16: Terminal Mult. | G16: Gordon Growth | J16: Football Field | K16: Sum-of-the-Parts
E17: Implied Price | F17: ='DCF Model'!G18 -> 232.50422 | G17: ='DCF Model'!C18 -> 225.46716 | I17: Implied Price | J17: =COMPS!G45 -> 244.03902 | K17: 243.7
E18: Difference | F18: =F17/$C$5-1 -> -0.08209939 | G18: =G17/$C$5-1 -> -0.10988093 | I18: Difference | J18: =J17/$C$5-1 -> -0.036561328 | K18: =K17/$C$5-1 -> -0.037899724
E21: Weighted average
E22: Price | F22: =AVERAGE(F17:G17,J17:K17) -> 236.4276
E23: Difference | F23: =AVERAGE(F18:G18,J18:K18) -> -0.066610343

Sheet Revenues
A1: =CoName -> Alphabet Inc. | C1: Hist. | D1: Hist. | E1: Hist. | F1: Hist. | G1: Hist. | H1: Hist. | I1: Hist. | J1: Hist. | K1: Hist. | L1: Hist. | M1: Hist. | N1: Hist. | O1: Hist. | P1: Hist. | Q1: Proj. | R1: Proj. | S1: Proj. | T1: Proj. | U1: Proj. | V1: Proj. | W1: Proj. | X1: Proj. | Y1: Proj. | Z1: Proj.
A2: Revenue Breakdown (Segment) | C2: 2021 | D2: 2022 | E2: Q123 | F2: Q223 | G2: Q323 | H2: Q423 | I2: 2023 | J2: Q124 | K2: Q224 | L2: Q324 | M2: Q424 | N2: 2024 | O2: Q125 | P2: Q225 | Q2: Q325E | R2: Q425E | S2: 2025E | T2: 2025E | U2: 2027E | V2: 2028E | W2: 2029E | X2: 2030E | Y2: 2031E | Z2: 2032E | AA2: CAGR
B3: Google Search & Other | C3: 148951 | D3: 162450 | E3: 40359 | F3: 42628 | G3: 44026 | H3: =I3-SUM(E3:G3) -> 48020 | I3: 175033 | J3: 46156 | K3: 48509 | L3: 49385 | M3: =N3-SUM(J3:L3) -> 54034 | N3: 198084 | O3: 50702 | P3: 54190 | Q3: =L3*(1+Q4) -> 55311.2 | R3: =M3*(1+R4) -> 62139.1 | S3: =SUM(O3:R3) -> 222342.3 | T3: =S3*(1+T4) -> 249571.39 | U3: =T3*(1+U4) -> 280135.07 | V3: =U3*(1+V4) -> 314441.73 | W3: =V3*(1+W4) -> 352949.75 | X3: =W3*(1+X4) -> 396173.64 | Y3: =X3*(1+Y4) -> 444690.93 | Z3: =Y3*(1+Z4) -> 499149.88 | AA3: =(Z3/S3)^(1/8)-1 -> 0.10637183
B4: Y/Y% | C4: =C3/104062-1 -> 0.43136784 | D4: =D3/C3-1 -> 0.090627119 | I4: =I3/D3-1 -> 0.077457679 | J4: =J3/E3-1 -> 0.14363587 | K4: =K3/F3-1 -> 0.13796096 | L4: =L3/G3-1 -> 0.12172353 | M4: =M3/H3-1 -> 0.12523948 | N4: =N3/I3-1 -> 0.13169517 | O4: =O3/J3-1 -> 0.09849207 | P4: =P3/K3-1 -> 0.11711229 | Q4: 0.12 | R4: 0.15 | S4: =S3/N3-1 -> 0.12246471 | T4: =S4 -> 0.12246471 | U4: =T4 -> 0.12246471 | V4: =U4 -> 0.12246471 | W4: =V4 -> 0.12246471 | X4: =W4 -> 0.12246471 | Y4: =X4 -> 0.12246471 | Z4: =Y4 -> 0.12246471
B5: Q/Q% | J5: =J3/H3-1 -> -0.03881716 | K5: =K3/J3-1 -> 0.050979288 | L5: =L3/K3-1 -> 0.018058505 | M5: =M3/L3-1 -> 0.094137896 | O5: =O3/M3-1 -> -0.061664878 | P5: =P3/O3-1 -> 0.06879413 | Q5: =Q3/P3-1 -> 0.020690164 | R5: =R3/Q3-1 -> 0.12344516
B6: Youtube ads | C6: 28845 | D6: 29243 | E6: 6693 | F6: 7665 | G6: 7952 | H6: =I6-SUM(E6:G6) -> 9200 | I6: 31510 | J6: 8090 | K6: 8663 | L6: 8921 | M6: =N6-SUM(J6:L6) -> 10473 | N6: 36147 | O6: 8927 | P6: 9796 | Q6: =L6*(1+Q7) -> 9983.4722 | R6: =M6*(1+R7) -> 11720.312 | S6: =SUM(O6:R6) -> 40426.784 | T6: =S6*(1+T7) -> 45213.293 | U6: =T6*(1+U7) -> 50566.521 | V6: =U6*(1+V7) -> 56553.569 | W6: =V6*(1+W7) -> 63249.479 | X6: =W6*(1+X7) -> 70738.182 | Y6: =X6*(1+Y7) -> 79113.543 | Z6: =Y6*(1+Z7) -> 88480.541 | AA6: =(Z6/S6)^(1/8)-1 -> 0.10286492
B7: Y/Y% | C7: =C6/19772-1 -> 0.45888125 | D7: =D6/C6-1 -> 0.013797885 | I7: =I6/D6-1 -> 0.077522826 | J7: =J6/E6-1 -> 0.20872553 | K7: =K6/F6-1 -> 0.13020222 | L7: =L6/G6-1 -> 0.12185614 | M7: =M6/H6-1 -> 0.13836957 | N7: =N6/I6-1 -> 0.14715963 | O7: =O6/J6-1 -> 0.10346106 | P7: =P6/K6-1 -> 0.1307861 | Q7: =AVERAGE(D7:P7) -> 0.11909788 | R7: =Q7 -> 0.11909788 | S7: =S6/N6-1 -> 0.11839943 | T7: =S7 -> 0.11839943 | U7: =T7 -> 0.11839943 | V7: =U7 -> 0.11839943 | W7: =V7 -> 0.11839943 | X7: =W7 -> 0.11839943 | Y7: =X7 -> 0.11839943 | Z7: =Y7 -> 0.11839943
B8: Q/Q% | J8: =J6/H6-1 -> -0.12065217 | K8: =K6/J6-1 -> 0.070828183 | L8: =L6/K6-1 -> 0.029781831 | M8: =M6/L6-1 -> 0.17397153 | O8: =O6/M6-1 -> -0.14761768 | P8: =P6/O6-1 -> 0.097345133 | Q8: =Q6/P6-1 -> 0.019137631 | R8: =R6/Q6-1 -> 0.17397153
B9: Google Network | C9: 31701 | D9: 32780 | E9: 7496 | F9: 7850 | G9: 7669 | H9: =I9-SUM(E9:G9) -> 8297 | I9: 31312 | J9: 7413 | K9: 7444 | L9: 7548 | M9: =N9-SUM(J9:L9) -> 7954 | N9: 30359 | O9: 7256 | P9: 7354 | Q9: =L9*(1+Q10) -> 7623.48 | R9: =M9*(1+R10) -> 8033.54 | S9: =SUM(O9:R9) -> 30267.02 | T9: =S9*(1+T10) -> 30175.319 | U9: =T9*(1+U10) -> 30083.895 | V9: =U9*(1+V10) -> 29992.749 | W9: =V9*(1+W10) -> 29901.878 | X9: =W9*(1+X10) -> 29811.283 | Y9: =X9*(1+Y10) -> 29720.963 | Z9: =Y9*(1+Z10) -> 29630.916 | AA9: =(Z9/S9)^(1/8)-1 -> -0.0026515286
B10: Y/Y% | C10: =C9/23090-1 -> 0.37293201 | D10: =D9/C9-1 -> 0.034036781 | I10: =I9/D9-1 -> -0.044783405 | J10: =J9/E9-1 -> -0.011072572 | K10: =K9/F9-1 -> -0.051719745 | L10: =L9/G9-1 -> -0.015777807 | M10: =M9/H9-1 -> -0.041340243 | N10: =N9/I9-1 -> -0.030435616 | O10: =O9/J9-1 -> -0.02117901 | P10: =P9/K9-1 -> -0.012090274 | Q10: 0.01 | R10: =Q10 -> 0.01 | S10: =S9/N9-1 -> -0.0030297441 | T10: =S10 -> -0.0030297441 | U10: =T10 -> -0.0030297441 | V10: =U10 -> -0.0030297441 | W10: =V10 -> -0.0030297441 | X10: =W10 -> -0.0030297441 | Y10: =X10 -> -0.0030297441 | Z10: =Y10 -> -0.0030297441
B11: Q/Q% | J11: =J9/H9-1 -> -0.10654453 | K11: =K9/J9-1 -> 0.0041818427 | L11: =L9/K9-1 -> 0.013970983 | M11: =M9/L9-1 -> 0.053789083 | O11: =O9/M9-1 -> -0.087754589 | P11: =P9/O9-1 -> 0.013506064 | Q11: =Q9/P9-1 -> 0.036644003 | R11: =R9/Q9-1 -> 0.053789083
A12: * | B12: Total advertising revenue | C12: =SUM(C9,C6,C3) -> 209497 | D12: =SUM(D9,D6,D3) -> 224473 | E12: =SUM(E9,E6,E3) -> 54548 | F12: =SUM(F9,F6,F3) -> 58143 | G12: =SUM(G9,G6,G3) -> 59647 | H12: =SUM(H9,H6,H3) -> 65517 | I12: =SUM(I9,I6,I3) -> 237855 | J12: =SUM(J9,J6,J3) -> 61659 | ... Z12: =SUM(Z9,Z6,Z3) -> 617261.34 | AA12: =(Z12/S12)^(1/8)-1 -> 0.097598469
B13: Y/Y% | C13: =C12/146924-1 -> 0.42588685 | D13: =D12/C12-1 -> 0.071485511 | I13: =I12/D12-1 -> 0.059615188 | J13: =J12/E12-1 -> 0.13036225 | K13: =K12/F12-1 -> 0.11132896 | L13: =L12/G12-1 -> 0.10406223 | M13: =M12/H12-1 -> 0.10598776 | N13: =N12/I12-1 -> 0.11240041 | O13: =O12/J12-1 -> 0.084756483 | P13: =P12/K12-1 -> 0.10406091 | ... S13: =S12/N12-1 -> 0.10751013 | T13: =T12/S12-1 -> 0.10894184 | U13: =U12/T12-1 -> 0.11024585 | V13: =V12/U12-1 -> 0.11143065 | W13: =W12/V12-1 -> 0.11250474 | X13: =X12/W12-1 -> 0.11347651 | Y13: =Y12/X12-1 -> 0.11435411 | Z13: =Z12/Y12-1 -> 0.11514538
B14: Q/Q% | J14: =J12/H12-1 -> -0.05888548 | K14: =K12/J12-1 -> 0.047957314 | L14: =L12/K12-1 -> 0.019159341 | M14: =M12/L12-1 -> 0.100328 | O14: =O12/M12-1 -> -0.07695174 | P14: =P12/O12-1 -> 0.066606863 | Q14: =Q12/P12-1 -> 0.022121562 | R14: =R12/Q12-1 -> 0.12308046
B15: % Of total revenue | C15: =C12/C26 -> 0.81314796 | D15: =D12/D26 -> 0.79365074 | E15: =E12/E26 -> 0.78164675 | F15: =F12/F26 -> 0.77935499 | G15: =G12/G26 -> 0.77773721 | H15: =H12/H26 -> 0.75908053 | I15: =I12/I26 -> 0.77377893 | J15: =J12/J26 -> 0.76557941 | ... P15: =P12/P26 -> 0.73982661 | Q15: =Q12/$Q$26 -> 0.71443565 | R15: =R12/R26 -> 0.72427828 | S15: =S12/S26 -> 0.72931864 | T15: =T12/T26 -> 0.699046 | U15: =U12/U26 -> 0.66501423 | V15: =V12/V26 -> 0.63048507 | W15: =W12/W26 -> 0.59846468 | X15: =X12/X26 -> 0.56855609 | Y15: =Y12/Y26 -> 0.54045899 | Z15: =Z12/Z26 -> 0.51395294
B16: Subscriptions, platforms, devices | C16: 28032 | D16: 29055 | E16: 7413 | F16: 8142 | G16: 8339 | H16: =I16-SUM(E16:G16) -> 10794 | I16: 34688 | J16: 8739 | K16: 9312 | L16: 10656 | M16: =N16-SUM(J16:L16) -> 11633 | N16: 40340 | O16: 10379 | P16: 11203 | Q16: =L16*(1+Q17) -> 12787.2 | R16: =M16*(1+R17) -> 13959.6 | S16: =SUM(O16:R16) -> 48328.8 | T16: =S16*(1+T17) -> 57899.675 | U16: =T16*(1+U17) -> 69365.935 | V16: =U16*(1+V17) -> 83102.936 | W16: =V16*(1+W17) -> 99560.366 | X16: =W16*(1+X17) -> 119276.97 | Y16: =X16*(1+Y17) -> 142898.19 | Z16: =Y16*(1+Z17) -> 171197.27 | AA16: =(Z16/S16)^(1/8)-1 -> 0.17128169
B17: Y/Y% | C17: =C16/21711-1 -> 0.29114274 | D17: =D16/C16-1 -> 0.036494007 | I17: =I16/D16-1 -> 0.19387369 | J17: =J16/E16-1 -> 0.17887495 | K17: =K16/F16-1 -> 0.14369934 | L17: =L16/G16-1 -> 0.27785106 | M17: =M16/H16-1 -> 0.077728368 | N17: =N16/I16-1 -> 0.16293819 | O17: =O16/J16-1 -> 0.18766449 | P17: =P16/K16-1 -> 0.20307131 | Q17: 0.2 | R17: =Q17 -> 0.2 | S17: =S16/N16-1 -> 0.19803669 | T17: =S17 -> 0.19803669 | U17: =T17 -> 0.19803669 | V17: =U17 -> 0.19803669 | W17: =V17 -> 0.19803669 | X17: =W17 -> 0.19803669 | Y17: =X17 -> 0.19803669 | Z17: =Y17 -> 0.19803669
B18: Q/Q% | J18: =J16/H16-1 -> -0.19038355 | K18: =K16/J16-1 -> 0.065568143 | L18: =L16/K16-1 -> 0.1443299 | M18: =M16/L16-1 -> 0.091685435 | O18: =O16/M16-1 -> -0.10779679 | P18: =P16/O16-1 -> 0.079391078 | Q18: =Q16/P16-1 -> 0.14140855 | R18: =R16/Q16-1 -> 0.091685435
B19: Google Cloud | C19: 19206 | D19: 26280 | E19: 7453 | F19: 8031 | G19: 8411 | H19: =I19-SUM(E19:G19) -> 9193 | I19: 33088 | J19: 9574 | K19: 10347 | L19: 11353 | M19: =N19-SUM(J19:L19) -> 11955 | N19: 43229 | O19: 12260 | P19: 13624 | Q19: =L19*(1+Q20) -> 15894.2 | R19: =M19*(1+R20) -> 16737 | S19: =SUM(O19:R19) -> 58515.2 | T19: =S19*(1+T20) -> 80109.477 | U19: =T19*(1+U20) -> 110342.77 | V19: =U19*(1+V20) -> 149733.96 | W19: =V19*(1+W20) -> 197417.44 | X19: =W19*(1+X20) -> 255159.56 | Y19: =X19*(1+Y20) -> 325076.24 | Z19: =Y19*(1+Z20) -> 409680.14 | AA19: =(Z19/S19)^(1/8)-1 -> 0.2754018 | AB19: Don't change the values, these adjustments are already in the 3 different operating revenues scenario
B20: Y/Y% | C20: =C19/13059-1 -> 0.47070986 | D20: =D19/C19-1 -> 0.3683224 | I20: =I19/D19-1 -> 0.25905632 | J20: =J19/E19-1 -> 0.28458339 | K20: =K19/F19-1 -> 0.28838252 | L20: =L19/G19-1 -> 0.34978005 | M20: =M19/H19-1 -> 0.30044599 | N20: =N19/I19-1 -> 0.30648574 | O20: =O19/J19-1 -> 0.28055149 | P20: =P19/K19-1 -> 0.31671016 | Q20: 0.4 | R20: 0.4 | S20: =S19/N19-1 -> 0.35360985 | T20: =AC21 -> 0.36903705 | U20: =AD21 -> 0.37739967 | V20: =AE21 -> 0.35698936 | W20: =AF21 -> 0.31845467 | X20: =AG21 -> 0.29248746 | Y20: =AH21 -> 0.27401157 | Z20: =AI21 -> 0.26025864 | AB20: 1
B21: Q/Q% | J21: =J19/H19-1 -> 0.041444577 | K21: =K19/J19-1 -> 0.080739503 | L21: =L19/K19-1 -> 0.097226249 | M21: =M19/L19-1 -> 0.053025632 | O21: =O19/M19-1 -> 0.025512338 | P21: =P19/O19-1 -> 0.11125612 | Q21: =Q19/P19-1 -> 0.16663241 | R21: =R19/Q19-1 -> 0.053025632 | AB21: Case Scenario | AC21: =CHOOSE($AB$20,AC23,AC24) -> 0.36903705 | AD21: =CHOOSE($AB$20,AD23,AD24) -> 0.37739967 | AE21: =CHOOSE($AB$20,AE23,AE24) -> 0.35698936 | AF21: =CHOOSE($AB$20,AF23,AF24) -> 0.31845467 | AG21: =CHOOSE($AB$20,AG23,AG24) -> 0.29248746 | AH21: =CHOOSE($AB$20,AH23,AH24) -> 0.27401157 | AI21: =CHOOSE($AB$20,AI23,AI24) -> 0.26025864
B22: Other bets | C22: 753 | D22: 1068 | E22: 288 | F22: 285 | G22: 297 | H22: =I22-SUM(E22:G22) -> 657 | I22: 1527 | J22: 495 | K22: 365 | L22: 388 | M22: =N22-SUM(J22:L22) -> 400 | N22: 1648 | O22: 450 | P22: 373 | Q22: =L22*(1+Q23) -> 464.43721 | R22: =M22*(1+R23) -> 478.80125 | S22: =SUM(O22:R22) -> 1766.2385 | T22: =S22*(1+T23) -> 1892.9601 | U22: =T22*(1+U23) -> 2028.7737 | V22: =U22*(1+V23) -> 2174.3313 | W22: =V22*(1+W23) -> 2330.3323 | X22: =W22*(1+X23) -> 2497.5258 | Y22: =X22*(1+Y23) -> 2676.7149 | Z22: =Y22*(1+Z23) -> 2868.7602 | AA22: =(Z22/S22)^(1/8)-1 -> 0.062504098
B23: Y/Y% | C23: =C22/657-1 -> 0.14611872 | D23: =D22/C22-1 -> 0.41832669 | I23: =I22/D22-1 -> 0.42977528 | J23: =J22/E22-1 -> 0.71875 | K23: =K22/F22-1 -> 0.28070175 | L23: =L22/G22-1 -> 0.30639731 | M23: =M22/H22-1 -> -0.39117199 | N23: =N22/I22-1 -> 0.079240341 | O23: =O22/J22-1 -> -0.090909091 | P23: =P22/K22-1 -> 0.021917808 | Q23: =AVERAGE(D23:P23) -> 0.19700312 | R23: =Q23 -> 0.19700312 | S23: =S22/N22-1 -> 0.071746638 | T23: =S23 -> 0.071746638 | U23: =T23 -> 0.071746638 | V23: =U23 -> 0.071746638 | W23: =V23 -> 0.071746638 | X23: =W23 -> 0.071746638 | Y23: =X23 -> 0.071746638 | Z23: =Y23 -> 0.071746638 | AB23: Efficient Capex | AC23: 0.36903705 | AD23: 0.37739967 | AE23: 0.35698936 | AF23: 0.31845467 | AG23: 0.29248746 | AH23: 0.27401157 | AI23: 0.26025864
B24: Q/Q% | J24: =J22/H22-1 -> -0.24657534 | K24: =K22/J22-1 -> -0.26262626 | L24: =L22/K22-1 -> 0.063013699 | M24: =M22/L22-1 -> 0.030927835 | O24: =O22/M22-1 -> 0.125 | P24: =P22/O22-1 -> -0.17111111 | Q24: =Q22/P22-1 -> 0.24513998 | R24: =R22/Q22-1 -> 0.030927835 | AB24: Inefficient Capex | AC24: 0.24792249 | AD24: 0.29969234 | AE24: 0.29969234 | AF24: 0.29969234 | AG24: 0.29969234 | AH24: 0.29969234 | AI24: 0.29969234
B25: Hedging gains (losses) | C25: 149 | D25: 1960 | E25: 84 | F25: 3 | G25: -1 | H25: =I25-SUM(E25:G25) -> 150 | I25: 236 | J25: 72 | K25: 102 | L25: 17 | M25: =N25-SUM(J25:L25) -> 20 | N25: 211 | O25: 260 | P25: -112 | S25: =SUM(O25:R25) -> 148
A26: * | B26: Total Net Revenue (by segments) | C26: =SUM(C25,C22,C19,C16,C12) -> 257637 | D26: =SUM(D25,D22,D19,D16,D12) -> 282836 | E26: =SUM(E25,E22,E19,E16,E12) -> 69786 | F26: =SUM(F25,F22,F19,F16,F12) -> 74604 | G26: =SUM(G25,G22,G19,G16,G12) -> 76693 | H26: =SUM(H25,H22,H19,H16,H12) -> 86311 | I26: =SUM(I25,I22,I19,I16,I12) -> 307394 | J26: =SUM(J25,J22,J19,J16,J12) -> 80539 | ... Z26: =SUM(Z25,Z22,Z19,Z16,Z12) -> 1201007.5 | AA26: =(Z26/S26)^(1/8)-1 -> 0.14668132
B27: Y/Y% | C27: =C26/182527-1 -> 0.41150076 | D27: =D26/C26-1 -> 0.097808156 | I27: =I26/D26-1 -> 0.086827702 | J27: =J26/E26-1 -> 0.15408535 | K27: =K26/F26-1 -> 0.13589084 | L27: =L26/G26-1 -> 0.15092642 | M27: =M26/H26-1 -> 0.11769068 | N27: =N26/I26-1 -> 0.13866243 | O27: =O26/J26-1 -> 0.12037646 | P27: =P26/K26-1 -> 0.13790092 | ... S27: =S26/N26-1 -> 0.1479248 | T27: =T26/S26-1 -> 0.15696529 | U27: =U26/T26-1 -> 0.16706213 | V27: =V26/U26-1 -> 0.17229927 | W27: =W26/V26-1 -> 0.17202844 | X27: =X26/W26-1 -> 0.17205035 | Y27: =Y26/X26-1 -> 0.17228658 | Z27: =Z26/Y26-1 -> 0.17265668
A29: Revenue Breakdown (Region) | C29: 2021 | D29: 2022 | E29: Q123 | F29: Q223 | G29: Q323 | H29: Q423 | I29: 2023 | J29: Q124 | K29: Q224 | L29: Q324 | M29: Q424 | N29: 2024 | O29: Q125 | P29: Q225 | Q29: Q325E | R29: Q425E | S29: 2025E | T29: 2025E | U29: 2027E | V29: 2028E | W29: 2029E | X29: 2030E | Y29: 2031E | Z29: 2032E
B30: United States | C30: 117854 | D30: 134814 | E30: 32864 | F30: 35073 | G30: 36354 | H30: 41995 | I30: 146286 | J30: 38737 | K30: 41196 | L30: 43139 | M30: 47375 | N30: 170447 | O30: 43964 | P30: 46063 | Q30: =Q33*Q26 -> 48755.274 | R30: =R33*R26 -> 54011.984 | S30: =S33*$S$26 -> 191934.43 | T30: =T33*$T$26 -> 222061.47 | U30: =U33*$U$26 -> 259159.53 | AA30: =(Z30/S30)^(1/8)-1 -> -1
B31: Y/Y% | C31: =C30/85014-1 -> 0.38628932 | D31: =D30/C30-1 -> 0.14390687 | I31: =I30/D30-1 -> 0.08509502 | J31: =J30/E30-1 -> 0.17870618 | K31: =K30/F30-1 -> 0.17457874 | L31: =L30/G30-1 -> 0.18663696 | M31: =M30/H30-1 -> 0.12811049 | N31: =N30/I30-1 -> 0.16516276 | O31: =O30/J30-1 -> 0.13493559 | P31: =P30/O30-1 -> 0.047743608 | Q31: =Q30/L30-1 -> 0.13019017 | R31: =R30/M30-1 -> 0.14009464
B32: Q/Q% | J32: =J30/H30-1 -> -0.077580664 | K32: =K30/J30-1 -> 0.063479361 | L32: =L30/K30-1 -> 0.047164773 | M32: =M30/L30-1 -> 0.098194209 | O32: =O30/M30-1 -> -0.072 | P32: =P30/O30-1 -> 0.047743608 | Q32: =Q30/P30-1 -> 0.058447644 | R32: =R30/Q30-1 -> 0.10781828
B33: % Of total revenue | C33: =C30/$C$54 -> 0.45744206 | D33: =D30/$D$54 -> 0.47665078 | I33: =I30/$I$54 -> 0.47589088 | J33: =J30/J54 -> 0.48097195 | K33: =K30/$K$54 -> 0.48613438 | L33: =L30/$L$54 -> 0.48872751 | M33: =M30/$M$54 -> 0.4910904 | N33: =N30/$N$54 -> 0.48696638 | O33: =O30/$O$54 -> 0.48722211 | P33: =P30/$P$54 -> 0.4776932 | Q33: =P33 -> 0.4776932 | R33: =Q33 -> 0.4776932 | S33: =R33 -> 0.4776932 | T33: =S33 -> 0.4776932 | U33: =T33 -> 0.4776932 | V33: =U33 -> 0.4776932 | W33: =V33 -> 0.4776932 | X33: =W33 -> 0.4776932 | ... Z33: =Y33 -> 0.4776932
B34: Other Americas | C34: 14404 | D34: 16976 | E34: 4080 | F34: 4511 | G34: 4553 | H34: 5176 | I34: 18320 | J34: 4653 | K34: 4938 | L34: 5093 | M34: 5734 | N34: 20418 | O34: 5233 | P34: 5735 | Q34: =Q37*$Q$26 -> 6070.1972 | R34: =R37*$R$26 -> 6724.6755 | S34: =S37*$S$26 -> 23896.488 | T34: =T37*$T$26 -> 27647.407 | U34: =U37*$U$26 -> 32266.242 | AA34: =(Z34/S34)^(1/8)-1 -> -1
B35: Y/Y% | C35: =C34/9417-1 -> 0.52957417 | D35: =D34/C34-1 -> 0.17856151 | I35: =I34/D34-1 -> 0.079170594 | J35: =J34/E34-1 -> 0.14044118 | K35: =K34/F34-1 -> 0.094657504 | L35: =L34/G34-1 -> 0.11860312 | M35: =M34/H34-1 -> 0.10780526 | N35: =N34/I34-1 -> 0.11451965 | O35: =O34/J34-1 -> 0.12465076 | P35: =P34/O34-1 -> 0.095929677 | Q35: =Q34/L34-1 -> 0.19187065 | R35: =R34/M34-1 -> 0.17277214
B36: Q/Q% | J36: =J34/H34-1 -> -0.10104328 | K36: =K34/J34-1 -> 0.061250806 | L36: =L34/K34-1 -> 0.031389226 | M36: =M34/L34-1 -> 0.12585902 | O36: =O34/M34-1 -> -0.087373561 | P36: =P34/O34-1 -> 0.095929677 | Q36: =Q34/P34-1 -> 0.058447644 | R36: =R34/Q34-1 -> 0.10781828
B37: % Of total revenue | C37: =C34/$C$54 -> 0.055908119 | D37: =D34/$D$54 -> 0.060020648 | I37: =I34/$I$54 -> 0.05959778 | J37: =J34/J54 -> 0.057773253 | K37: =K34/$K$54 -> 0.058270987 | L37: =L34/$L$54 -> 0.057699279 | M37: =M34/$M$54 -> 0.059438783 | N37: =N34/$N$54 -> 0.058334143 | O37: =O34/$O$54 -> 0.057993661 | P37: =P34/$P$54 -> 0.059474427 | Q37: =P37 -> 0.059474427 | R37: =Q37 -> 0.059474427 | S37: =R37 -> 0.059474427 | T37: =S37 -> 0.059474427 | U37: =T37 -> 0.059474427 | V37: =U37 -> 0.059474427 | W37: =V37 -> 0.059474427 | X37: =W37 -> 0.059474427 | ... Z37: =Y37 -> 0.059474427
A38: * | B38: Total Americas Revenue | C38: =SUM(C34,C30) -> 132258 | D38: =SUM(D34,D30) -> 151790 | E38: =SUM(E34,E30) -> 36944 | F38: =SUM(F34,F30) -> 39584 | G38: =SUM(G34,G30) -> 40907 | H38: =SUM(H34,H30) -> 47171 | I38: =SUM(I34,I30) -> 164606 | J38: =SUM(J34,J30) -> 43390 | ... P38: =SUM(P34,P30) -> 51798 | Q38: =Q41*Q26 -> 54825.471 | R38: =R41*$R$26 -> 60736.659 | S38: =SUM(S34,S30) -> 215830.91 | T38: =SUM(T34,T30) -> 249708.88 | U38: =SUM(U34,U30) -> 291425.77 | V38: =SUM(V34,V30) -> 0 | W38: =SUM(W34,W30) -> 0 | X38: =SUM(X34,X30) -> 0 | Y38: =SUM(Y34,Y30) -> 0 | Z38: =SUM(Z34,Z30) -> 0 | AA38: =(Z38/S38)^(1/8)-1 -> -1
B39: Y/Y% | C39: =C38/(85014+9417)-1 -> 0.4005782 | D39: =D38/C38-1 -> 0.14768105 | I39: =I38/D38-1 -> 0.08443244 | J39: =J38/E38-1 -> 0.17448029 | K39: =K38/F38-1 -> 0.1654709 | L39: =L38/G38-1 -> 0.17906471 | M39: =M38/H38-1 -> 0.12588243 | N39: =N38/I38-1 -> 0.15952638 | O39: =O38/J38-1 -> 0.13383268 | P39: =P38/O38-1 -> 0.052869077 | Q39: =Q38/L38-1 -> 0.13670325 | R39: =R38/M38-1 -> 0.14362272
B40: Q/Q% | J40: =J38/H38-1 -> -0.08015518 | K40: =K38/J38-1 -> 0.063240378 | L40: =L38/K38-1 -> 0.045476221 | M40: =M38/L38-1 -> 0.10111544 | O40: =O38/M38-1 -> -0.073659832 | P40: =P38/O38-1 -> 0.052869077 | Q40: =Q38/P38-1 -> 0.058447644 | R40: =R38/Q38-1 -> 0.10781828
B41: % Of total revenue | C41: =C38/$C$54 -> 0.51335018 | D41: =D38/$D$54 -> 0.53667143 | I41: =I38/$I$54 -> 0.53548866 | J41: =J38/J54 -> 0.5387452 | K41: =K38/$K$54 -> 0.54440537 | L41: =L38/$L$54 -> 0.54642679 | M41: =M38/$M$54 -> 0.55052919 | N41: =N38/$N$54 -> 0.54530053 | O41: =O38/$O$54 -> 0.54521577 | P41: =P38/$P$54 -> 0.53716763 | Q41: =P41 -> 0.53716763 | R41: =Q41 -> 0.53716763 | S41: =R41 -> 0.53716763 | T41: =S41 -> 0.53716763 | U41: =T41 -> 0.53716763 | V41: =U41 -> 0.53716763 | W41: =V41 -> 0.53716763 | X41: =W41 -> 0.53716763 | ... Z41: =Y41 -> 0.53716763
...

Sheet Assumptions
A1: =CoName -> Alphabet Inc. | C1: Hist. | D1: Hist. | E1: Hist. | F1: Proj. | G1: Proj. | H1: Proj. | I1: Proj. | J1: Proj. | K1: Proj. | L1: Proj. | M1: Proj.
A2: * | B2: Income Statement | C2: 44926 | D2: 45291 | E2: 45657 | F2: 46022 | G2: 46387 | H2: 46752 | I2: 47118 | J2: 47483 | K2: 47848 | L2: 48213 | M2: 48579
B3: Operating Case | D3: 1 | O3: Capex Case | P3: 1
D4: Variance
B5: Street Case | D5: 0 | F5: 0.1479248 | G5: 0.13932681 | H5: 0.15141023 | I5: 0.15657367 | J5: 0.16189467 | K5: 0.16737261 | L5: 0.17300063 | M5: 0.17876527 | O5: Base Capex case | P5: 0.212 | Q5: =P5-0.015 -> 0.197 | R5: =Q5-0.015 -> 0.182 | S5: =R5-0.015 -> 0.167 | T5: =S5-0.015 -> 0.152 | U5: =T5-0.015 -> 0.137 | V5: =U5-0.015 -> 0.122 | W5: =V5-0.015 -> 0.107
B6: Optimistic Case | D6: 0.025 | F6: =Revenues!S27 -> 0.1479248 | G6: =Revenues!T27 -> 0.15696529 | H6: =Revenues!U27 -> 0.16706213 | I6: =Revenues!V27 -> 0.17229927 | J6: =Revenues!W27 -> 0.17202844 | K6: =Revenues!X27 -> 0.17205035 | L6: =Revenues!Y27 -> 0.17228658 | M6: =Revenues!Z27 -> 0.17265668 | O6: Pessimistic Capex case | P6: 0.212 | Q6: =P6-0.01 -> 0.202 | R6: =Q6-0.01 -> 0.192 | S6: =R6-0.01 -> 0.182 | T6: =S6-0.01 -> 0.172 | U6: =T6-0.01 -> 0.162 | V6: =U6-0.01 -> 0.152 | W6: =V6-0.01 -> 0.142
B7: Pessimistic Case | D7: -0.025 | F7: =F5+$D$7 -> 0.1229248 | G7: =G5+$D$7 -> 0.11432681 | H7: =H5+$D$7 -> 0.12641023 | I7: =I5+$D$7 -> 0.13157367 | J7: =J5+$D$7 -> 0.13689467 | K7: =K5+$D$7 -> 0.14237261 | L7: =L5+$D$7 -> 0.14800063 | M7: =M5+$D$7 -> 0.15376527
B9: Revenue Growth | C9: =Revenues!D27 -> 0.097808156 | D9: =Revenues!I27 -> 0.086827702 | E9: =Revenues!N27 -> 0.13866243 | F9: =CHOOSE(ScenarioREV,F5,F6,F7) -> 0.1479248 | G9: =CHOOSE(ScenarioREV,G5,G6,G7) -> 0.13932681 | H9: =CHOOSE(ScenarioREV,H5,H6,H7) -> 0.15141023 | I9: =CHOOSE(ScenarioREV,I5,I6,I7) -> 0.15657367 | J9: =CHOOSE(ScenarioREV,J5,J6,J7) -> 0.16189467 | K9: =CHOOSE(ScenarioREV,K5,K6,K7) -> 0.16737261 | L9: =CHOOSE(ScenarioREV,L5,L6,L7) -> 0.17300063 | M9: =CHOOSE(ScenarioREV,M5,M6,M7) -> 0.17876527
B10: COGS % of sales | C10: =IncState!C18/IncState!C17 -> 0.44620557 | D10: =IncState!D18/IncState!D17 -> 0.43374952 | E10: =IncState!E18/IncState!E17 -> 0.41799565 | F10: =E10 -> 0.41799565 | G10: =F10 -> 0.41799565 | H10: =G10 -> 0.41799565 | I10: =H10 -> 0.41799565 | J10: =I10 -> 0.41799565 | K10: =J10 -> 0.41799565 | L10: =K10 -> 0.41799565 | M10: =L10 -> 0.41799565
B11: R&D % of sales | C11: =IncState!C19/IncState!C17 -> 0.1396569 | D11: =IncState!D19/IncState!D17 -> 0.14778102 | E11: =IncState!E19/IncState!E17 -> 0.14092418 | F11: =E11 -> 0.14092418 | G11: =F11 -> 0.14092418 | H11: =G11 -> 0.14092418 | I11: =H11 -> 0.14092418 | J11: =I11 -> 0.14092418 | K11: =J11 -> 0.14092418 | L11: =K11 -> 0.14092418 | M11: =L11 -> 0.14092418
B12: SG&A % of sales | C12: =IncState!C20/IncState!C17 -> 0.14952481 | D12: =IncState!D20/IncState!D17 -> 0.14425135 | E12: =IncState!E20/IncState!E17 -> 0.1199824 | F12: =E12 -> 0.1199824 | G12: =F12 -> 0.1199824 | H12: =G12 -> 0.1199824 | I12: =H12 -> 0.1199824 | J12: =I12 -> 0.1199824 | K12: =J12 -> 0.1199824 | L12: =K12 -> 0.1199824 | M12: =L12 -> 0.1199824
B13: Amortization $ Amt | C13: 0 | D13: 0 | E13: 0 | F13: 0 | G13: 0 | H13: 0 | I13: 0 | J13: 0 | K13: 0 | L13: 0 | M13: 0
B14: Non recurring income / (expense) | C14: 0 | D14: 0 | E14: 0 | F14: -1400 | G14: 0 | H14: 0 | I14: 0 | J14: 0 | K14: 0 | L14: 0 | M14: 0
B15: Other Income / (expense) | C15: =IncState!C28 -> -5331 | D15: =IncState!D28 -> -2390 | E15: =IncState!E28 -> 3211 | F15: 0 | G15: 0 | H15: 0 | I15: 0 | J15: 0 | K15: 0 | L15: 0 | M15: 0
B16: Effective tax rate | C16: =IncState!C11 -> 0.15920817 | D16: =IncState!D11 -> 0.13950386 | E16: =IncState!E11 -> 0.16439511 | F16: =E16+0.016 -> 0.18039511 | G16: =F16 -> 0.18039511 | H16: =G16 -> 0.18039511 | I16: =H16 -> 0.18039511 | J16: =I16 -> 0.18039511 | K16: =J16 -> 0.18039511 | L16: =K16 -> 0.18039511 | M16: =L16 -> 0.18039511
B17: Dividend Payout Rate | C17: 0 | D17: 0 | E17: =IncState!E12 -> 0.073543219 | F17: =IncState!F12 -> 0.0854 | G17: =F17 -> 0.0854 | H17: =G17 -> 0.0854 | I17: =H17 -> 0.0854 | J17: =I17 -> 0.0854 | K17: =J17 -> 0.0854 | L17: =K17 -> 0.0854 | M17: =L17 -> 0.0854
B18: Basic WASO | C18: =IncState!C40 -> 13065.795 | D18: =IncState!D40 -> 12592.123 | E18: =IncState!E40 -> 12314.637 | F18: =E18 -> 12314.637 | G18: =F18 -> 12314.637 | H18: =G18 -> 12314.637 | I18: =H18 -> 12314.637 | J18: =I18 -> 12314.637 | K18: =J18 -> 12314.637 | L18: =K18 -> 12314.637 | M18: =L18 -> 12314.637
B19: Diluted WASO | C19: =IncState!C41 -> 13151.754 | D19: =IncState!D41 -> 12678.966 | E19: =IncState!E41 -> 12452.488 | F19: =E19 -> 12452.488 | G19: =F19 -> 12452.488 | H19: =G19 -> 12452.488 | I19: =H19 -> 12452.488 | J19: =I19 -> 12452.488 | K19: =J19 -> 12452.488 | L19: =K19 -> 12452.488 | M19: =L19 -> 12452.488
A21: * | B21: Debt | C21: 44926 | D21: 45291 | E21: 45657 | F21: 46022 | G21: 46387 | H21: 46752 | I21: 47118 | J21: 47483 | K21: =K2 -> 47848 | L21: =L2 -> 48213 | M21: =M2 -> 48579
B22: Interest rate on Revolver | E22: 0.044 | F22: =E22 -> 0.044 | G22: =F22 -> 0.044 | H22: =G22 -> 0.044 | I22: =H22 -> 0.044 | J22: =I22 -> 0.044 | K22: =J22 -> 0.044 | L22: =K22 -> 0.044 | M22: =L22 -> 0.044
B23: Interest rate on long-term debt | E23: 0.044 | F23: =E23 -> 0.044 | G23: =F23 -> 0.044 | H23: =G23 -> 0.044 | I23: =H23 -> 0.044 | J23: =I23 -> 0.044 | K23: =J23 -> 0.044 | L23: =K23 -> 0.044 | M23: =L23 -> 0.044
B24: Interest rate on cash | C24: =IncState!C30/SUM(BalSheet!C16:C17) -> 0.019110072 | D24: =IncState!D30/SUM(BalSheet!D16:D17) -> 0.03484619 | E24: =IncState!E30/SUM(BalSheet!E16:E17) -> 0.046854909 | F24: =E24 -> 0.046854909 | G24: =F24 -> 0.046854909 | H24: =G24 -> 0.046854909 | I24: =H24 -> 0.046854909 | J24: =I24 -> 0.046854909 | K24: =J24 -> 0.046854909 | L24: =K24 -> 0.046854909 | M24: =L24 -> 0.046854909
B26: Issuance of long-term debt | F26: 0 | G26: 0 | H26: 0 | I26: 0 | J26: 0 | K26: 0 | L26: 0 | M26: 0
B27: Repayment of long-term debt | F27: 0 | G27: 0 | H27: 0 | I27: 0 | J27: 0 | K27: 0 | L27: 0 | M27: 0
A29: * | B29: Calcs | C29: 44926 | D29: 45291 | E29: 45657 | F29: 46022 | G29: 46387 | H29: 46752 | I29: 47118 | J29: 47483 | K29: 2030 | L29: =K29+1 -> 2031 | M29: =L29+1 -> 2032
B30: CapEx % of Sales | D30: =32300/IncState!D17 -> 0.10507687 | E30: =52500/IncState!E17 -> 0.14999229 | F30: =CHOOSE(ScenarioCAPEX,P5,P6) -> 0.212 | G30: =CHOOSE(ScenarioCAPEX,Q5,Q6) -> 0.197 | H30: =CHOOSE(ScenarioCAPEX,R5,R6) -> 0.182 | I30: =CHOOSE(ScenarioCAPEX,S5,S6) -> 0.167 | J30: =CHOOSE(ScenarioCAPEX,T5,T6) -> 0.152 | K30: =CHOOSE(ScenarioCAPEX,U5,U6) -> 0.137 | L30: =CHOOSE(ScenarioCAPEX,V5,V6) -> 0.122 | M30: =CHOOSE(ScenarioCAPEX,W5,W6) -> 0.107
B31: Depreciation % of beginning PP&E | D31: =11946/BalSheet!C23 -> 0.10602833 | E31: =15311/BalSheet!D23 -> 0.11396777 | F31: =E31+0.005 -> 0.11896777 | G31: =F31 -> 0.11896777 | H31: =G31 -> 0.11896777 | I31: =H31 -> 0.11896777 | J31: =I31 -> 0.11896777 | K31: =J31 -> 0.11896777 | L31: =K31 -> 0.11896777 | M31: =L31 -> 0.11896777
B32: Share issuance / (repurchases) | C32: -59300 | D32: -62184 | E32: -62047 | F32: 0 | G32: 0 | H32: 0 | I32: 0 | J32: 0 | K32: 0 | L32: 0 | M32: 0
A34: * | B34: Shareholder information | C34: 44926 | D34: 45291 | E34: 45657 | F34: 46022 | G34: 46387 | H34: 46752 | I34: 47118 | J34: 47483 | K34: 2030 | L34: =K34+1 -> 2031 | M34: =L34+1 -> 2032
B35: Dividend payout ratio | C35: =C17 -> 0 | D35: =D17 -> 0 | E35: =E17 -> 0.073543219 | F35: =F17 -> 0.0854 | G35: =G17 -> 0.0854 | H35: =H17 -> 0.0854 | I35: =I17 -> 0.0854 | J35: =J17 -> 0.0854 | ... M35: =M17 -> 0.0854
B36: Basic WASO | C36: =C18 -> 13065.795 | D36: =D18 -> 12592.123 | E36: =E18 -> 12314.637 | F36: =F18 -> 12314.637 | G36: =G18 -> 12314.637 | H36: =H18 -> 12314.637 | I36: =I18 -> 12314.637 | J36: =J18 -> 12314.637 | ... M36: =M18 -> 12314.637
B37: Diluted WASO | C37: =C19 -> 13151.754 | D37: =D19 -> 12678.966 | E37: =E19 -> 12452.488 | F37: =F19 -> 12452.488 | G37: =G19 -> 12452.488 | H37: =H19 -> 12452.488 | I37: =I19 -> 12452.488 | J37: =J19 -> 12452.488 | ... M37: =M19 -> 12452.488
A39: * | B39: Balance Sheet - Assets | C39: 44926 | D39: 45291 | E39: 45657 | F39: 46022 | G39: 46387 | H39: 46752 | I39: 47118 | J39: 47483 | K39: 2030 | L39: =K39+1 -> 2031 | M39: =L39+1 -> 2032
B40: Operating Cash % of sales | C40: =BalSheet!C16/IncState!C17 -> 0.077355782 | D40: =BalSheet!D16/IncState!D17 -> 0.078231846 | E40: =BalSheet!E16/IncState!E17 -> 0.067042266 | F40: =E40 -> 0.067042266 | G40: =F40 -> 0.067042266 | H40: =G40 -> 0.067042266 | I40: =H40 -> 0.067042266 | J40: =I40 -> 0.067042266 | K40: =J40 -> 0.067042266 | L40: =K40 -> 0.067042266 | M40: =L40 -> 0.067042266
B41: Accounts receivable % of sales | C41: =BalSheet!C18/IncState!C17 -> 0.1423369 | D41: =BalSheet!D18/IncState!D17 -> 0.15603428 | E41: =BalSheet!E18/IncState!E17 -> 0.14953517 | F41: =E41 -> 0.14953517 | G41: =F41 -> 0.14953517 | H41: =G41 -> 0.14953517 | I41: =H41 -> 0.14953517 | J41: =I41 -> 0.14953517 | K41: =J41 -> 0.14953517 | L41: =K41 -> 0.14953517 | M41: =L41 -> 0.14953517
B42: Inventories % of COGS | C42: =BalSheet!C19/IncState!C18 -> 0.021156391 | D42: =BalSheet!D19/IncState!D18 -> 0 | E42: =BalSheet!E19/IncState!E18 -> 0 | F42: =E42 -> 0 | G42: =F42 -> 0 | H42: =G42 -> 0 | I42: =H42 -> 0 | J42: =I42 -> 0 | K42: =J42 -> 0 | L42: =K42 -> 0 | M42: =L42 -> 0
B43: Other current assets % of sales | C43: =BalSheet!C20/IncState!C17 -> 0.028656182 | D43: =BalSheet!D20/IncState!D17 -> 0.041152397 | E43: =BalSheet!E20/IncState!E17 -> 0.044894834 | F43: =E43 -> 0.044894834 | G43: =F43 -> 0.044894834 | H43: =G43 -> 0.044894834 | I43: =H43 -> 0.044894834 | J43: =I43 -> 0.044894834 | K43: =J43 -> 0.044894834 | L43: =K43 -> 0.044894834 | M43: =L43 -> 0.044894834
B45: Investments in unconsolidated entities | C45: =BalSheet!C25 -> 30492 | D45: =BalSheet!D25 -> 31008 | E45: =BalSheet!E25 -> 37982 | F45: =E45 -> 37982 | G45: =F45 -> 37982 | H45: =G45 -> 37982 | I45: =H45 -> 37982 | J45: =I45 -> 37982 | K45: =J45 -> 37982 | L45: =K45 -> 37982 | M45: =L45 -> 37982
B46: Other long-term assets % of sales | C46: =BalSheet!C26/IncState!C17 -> 0.092863002 | D46: =BalSheet!D26/IncState!D17 -> 0.11812527 | E46: =BalSheet!E26/IncState!E17 -> 0.13039901 | F46: =E46 -> 0.13039901 | G46: =F46 -> 0.13039901 | H46: =G46 -> 0.13039901 | I46: =H46 -> 0.13039901 | J46: =I46 -> 0.13039901 | K46: =J46 -> 0.13039901 | L46: =K46 -> 0.13039901 | M46: =L46 -> 0.13039901
A48: * | B48: Balance Sheet - Liabilities | C48: 44926 | D48: 45291 | E48: 45657 | F48: 46022 | G48: 46387 | H48: 46752 | I48: 47118 | J48: 47483 | K48: 2030 | L48: =K48+1 -> 2031 | M48: =L48+1 -> 2032
...

Sheet Capex
A1: Capex drivers | G1: Hist. | H1: Hist. | I1: Hist. | J1: Proj. | K1: Proj. | L1: Proj. | M1: Proj. | N1: Proj. | O1: Proj. | P1: Proj. | Q1: Proj.
A2: Total Capex | B2: 85000 | C2: $B | E2: * | F2: Capex Calcs | G2: 44926 | H2: 45291 | I2: 45657 | J2: 46022 | K2: 46387 | L2: 46752 | M2: 47118 | N2: 47483 | O2: 2030 | P2: =O2+1 -> 2031 | Q2: =P2+1 -> 2032
A3: Search & Other | B3: 0.15 | C3: =$C$9*B3*0.001 -> 12.75 | F3: Capex | G3: 24640 | H3: 32251 | I3: 52535 | J3: =Calcs!F7 -> 85180.401 | K3: =Calcs!G7 -> 90181.688 | L3: =Calcs!H7 -> 95929.815 | M3: =Calcs!I7 -> 101805.68 | N3: =Calcs!J7 -> 107662.85 | O3: =Calcs!K7 -> 113279.77 | P3: =Calcs!L7 -> 118328.64 | Q3: =Calcs!M7 -> 122332.3
A4: YT ads | B4: 0.1 | C4: =$C$9*B4*0.001 -> 8.5 | F4: Changes in Capex | G4: =G3/22281-1 -> 0.10587496 | H4: =H3/G3-1 -> 0.30888799 | I4: =I3/H3-1 -> 0.62894174 | J4: =J3/I3-1 -> 0.62140289 | K4: =K3/J3-1 -> 0.058714064 | L4: =L3/K3-1 -> 0.063739404 | M4: =M3/L3-1 -> 0.061251664 | N4: =N3/M3-1 -> 0.057532871 | O4: =O3/N3-1 -> 0.052171366 | ... Q4: =Q3/P3-1 -> 0.033835117
A5: Google network | B5: 0.05 | C5: =$C$9*B5*0.001 -> 4.25 | E5: * | F5: Changes in segment revenue
A6: Subscription/Platforms/Devices | B6: 0.07 | C6: =$C$9*B6*0.001 -> 5.95 | F6: Google Search & Other | G6: =Revenues!D3 -> 162450 | H6: =Revenues!I3 -> 175033 | I6: =Revenues!N3 -> 198084 | J6: =Revenues!S3 -> 222342.3 | K6: =Revenues!T3 -> 249571.39 | L6: =Revenues!U3 -> 280135.07 | M6: =Revenues!V3 -> 314441.73 | N6: =Revenues!W3 -> 352949.75 | O6: =Revenues!X3 -> 396173.64 | P6: =Revenues!Y3 -> 444690.93 | Q6: =Revenues!Z3 -> 499149.88
A7: Google cloud | B7: 0.6 | C7: =$C$9*B7*0.001 -> 51 | F7: Delta impact | H7: =(H6-G6)*0.001 -> 12.583 | I7: =(I6-H6)*0.001 -> 23.051 | J7: =(J6-I6)*0.001 -> 24.2583 | K7: =(K6-J6)*0.001 -> 27.229086 | L7: =(L6-K6)*0.001 -> 30.563688 | M7: =(M6-L6)*0.001 -> 34.306661 | N7: =(N6-M6)*0.001 -> 38.508016 | O7: =(O6-N6)*0.001 -> 43.22389 | ... Q7: =(Q6-P6)*0.001 -> 54.458947
A8: Other Bets | B8: 0.03 | C8: =$C$9*B8*0.001 -> 2.55 | F8: Rev/$B Capex | H8: =H7/$C$3 -> 0.98690196 | I8: =I7/$C$3 -> 1.8079216 | J8: =J7/C3 -> 1.9026118 | K8: =K7/$C$3 -> 2.1356146 | L8: =L7/$C$3 -> 2.397152 | M8: =M7/$C$3 -> 2.6907185 | N8: =N7/$C$3 -> 3.0202366 | O8: =O7/$C$3 -> 3.390109 | P8: =P7/$C$3 -> 3.8052777 | Q8: =Q7/$C$3 -> 4.2712899
A9: Total Weighting | B9: =SUM(B3:B8) -> 1 | C9: =B9*$B$2 -> 85000
F10: Youtube | G10: =Revenues!D6 -> 29243 | H10: =Revenues!I6 -> 31510 | I10: =Revenues!N6 -> 36147 | J10: =Revenues!S6 -> 40426.784
F11: Delta impact | H11: =(H10-G10)*0.001 -> 2.267 | I11: =(I10-H10)*0.001 -> 4.637 | J11: =(J10-I10)*0.001 -> 4.2797844
F12: Rev/$B Capex | J12: =J11/C4 -> 0.50350404
F14: Google Network | G14: =Revenues!D9 -> 32780 | H14: =Revenues!I9 -> 31312 | I14: =Revenues!N9 -> 30359 | J14: =Revenues!S9 -> 30267.02
F15: Delta impact | H15: =(H14-G14)*0.001 -> -1.468 | I15: =(I14-H14)*0.001 -> -0.953 | J15: =(J14-I14)*0.001 -> -0.09198
F16: Rev/$B Capex | J16: =J15/C5 -> -0.021642353
F18: Subscriptions | G18: =Revenues!D16 -> 29055 | H18: =Revenues!I16 -> 34688 | I18: =Revenues!N16 -> 40340 | J18: =Revenues!S16 -> 48328.8
F19: Delta impact | H19: =(H18-G18)*0.001 -> 5.633 | I19: =(I18-H18)*0.001 -> 5.652 | J19: =(J18-I18)*0.001 -> 7.9888
F20: Rev/$B Capex | J20: =J19/C6 -> 1.3426555
K21: =K22/J22-1 -> 0.24792249 | L21: =L22/K22-1 -> 0.29969234 | M21: =M22/L22-1 -> 0.29969234 | N21: =N22/M22-1 -> 0.29969234 | O21: =O22/N22-1 -> 0.29969234 | P21: =P22/O22-1 -> 0.29969234 | Q21: =Q22/P22-1 -> 0.29969234
F22: Google Cloud | G22: 26280 | H22: 33088 | I22: 43229 | J22: =Revenues!S19 -> 58515.2 | K22: 73022.434 | L22: 94906.698 | M22: 123349.51 | N22: 160316.41 | O22: 208362.01 | P22: 270806.51 | Q22: 351965.14
F23: Delta impact | H23: =(H22-G22)*0.001 -> 6.808 | I23: =(I22-H22)*0.001 -> 10.141 | J23: =(J22-I22)*0.001 -> 15.2862 | K23: =(K22-J22)*0.001 -> 14.507234 | L23: =(L22-K22)*0.001 -> 21.884264 | M23: =(M22-L22)*0.001 -> 28.44281 | N23: =(N22-M22)*0.001 -> 36.966902 | O23: =(O22-N22)*0.001 -> 48.045599 | ... Q23: =(Q22-P22)*0.001 -> 81.158635
F24: Rev/$B Capex | H24: =H23/$C$7 -> 0.1334902 | I24: =I23/$C$7 -> 0.19884314 | J24: =J23/$C$7 -> 0.29972941 | K24: =K23/($B$7*K3*0.001) -> 0.26811123 | L24: =L23/($B$7*L3*0.001) -> 0.38021311 | M24: =M23/($B$7*M3*0.001) -> 0.4656389 | N24: =N23/($B$7*N3*0.001) -> 0.57226336 | O24: =O23/($B$7*O3*0.001) -> 0.70688704 | P24: =P23/($B$7*P3*0.001) -> 0.87953488 | Q24: =Q23/($B$7*Q3*0.001) -> 1.1057128
F25: Rev/$B Capex Mean | K25: 0.4 | L25: =K25+0.25 -> 0.65 | M25: =L25+0.25 -> 0.9 | N25: =M25+0.25 -> 1.15 | O25: =N25+0.25 -> 1.4 | P25: =O25+0.25 -> 1.65 | Q25: =P25+0.25 -> 1.9
F26: Rev/$B Capex increase | K26: =K25/K24 -> 1.4919181 | L26: =L25/L24 -> 1.7095676 | M26: =M25/M24 -> 1.9328282 | N26: =N25/N24 -> 2.0095643 | O26: =O25/O24 -> 1.9805145 | P26: =P25/P24 -> 1.8759915 | Q26: =Q25/Q24 -> 1.7183485
F27: Delta Increase | K27: =K23*K26 -> 21.643605 | L27: =L23*L26 -> 37.412628 | M27: =M23*M26 -> 54.975065 | N27: =N23*N26 -> 74.287366 | O27: =O23*O26 -> 95.155004 | P27: =P23*P26 -> 117.14535 | Q27: =Q23*Q26 -> 139.45882
F28: Adjusted Google Clound Rev | K28: =J22+(K27*1000) -> 80158.805 | L28: =K22+(L27*1000) -> 110435.06 | M28: =L22+(M27*1000) -> 149881.76 | N28: =M22+(N27*1000) -> 197636.87 | O28: =N22+(O27*1000) -> 255471.41 | P28: =O22+(P27*1000) -> 325507.36 | Q28: =P22+(Q27*1000) -> 410265.33
F29: Adjust y/y% | K29: =K28/J22-1 -> 0.36988005 | L29: =L28/K28-1 -> 0.37770345 | M29: =M28/L28-1 -> 0.35719363 | N29: =N28/M28-1 -> 0.31861855 | O29: =O28/N28-1 -> 0.29263031 | P29: =P28/O28-1 -> 0.27414396 | Q29: =Q28/P28-1 -> 0.26038726
F31: Other Bets | G31: =Revenues!D22 -> 1068 | H31: =Revenues!I22 -> 1527 | I31: =Revenues!N22 -> 1648 | J31: =Revenues!S22 -> 1766.2385
F32: Delta impact | H32: =(H31-G31)*0.001 -> 0.459 | I32: =(I31-H31)*0.001 -> 0.121 | J32: =(J31-I31)*0.001 -> 0.11823846
F33: Rev/$B Capex | J33: =J32/C8 -> 0.046368024
K35: 0.41491776 | L35: 0.33944567 | M35: 0.32620503 | N35: 0.3167992 | O35: 0.31008779 | P35: 0.30532718 | Q35: 0.3020102

Sheet Calcs
A1: =CoName -> Alphabet Inc. | C1: Hist. | D1: Hist. | E1: Hist. | F1: Proj. | G1: Proj. | H1: Proj. | I1: Proj. | J1: Proj. | K1: Proj. | L1: Proj. | M1: Proj.
A2: Net PP&E | C2: 2022 | D2: =DATE(YEAR(E2)-1,MONTH(E2),DAY(E2)) -> 44959 | E2: =DATE(YEAR(F2)-1,MONTH(F2),DAY(F2)) -> 45324 | F2: =Inputs!C6 -> 45690 | G2: =DATE(YEAR(F2)+1,MONTH(F2),DAY(F2)) -> 46055 | H2: =DATE(YEAR(G2)+1,MONTH(G2),DAY(G2)) -> 46420 | I2: =DATE(YEAR(H2)+1,MONTH(H2),DAY(H2)) -> 46785 | J2: =DATE(YEAR(I2)+1,MONTH(I2),DAY(I2)) -> 47151 | K2: =DATE(YEAR(J2)+1,MONTH(J2),DAY(J2)) -> 47516 | L2: =DATE(YEAR(K2)+1,MONTH(K2),DAY(K2)) -> 47881 | M2: =DATE(YEAR(L2)+1,MONTH(L2),DAY(L2)) -> 48246
B3: Capital expenditure % of sales | F3: =Assumptions!F30 -> 0.212 | G3: =Assumptions!G30 -> 0.197 | H3: =Assumptions!H30 -> 0.182 | I3: =Assumptions!I30 -> 0.167 | J3: =Assumptions!J30 -> 0.152 | K3: =Assumptions!K30 -> 0.137 | L3: =Assumptions!L30 -> 0.122 | M3: =Assumptions!M30 -> 0.107
B4: Depreciation % of PP&E | F4: =Assumptions!F31 -> 0.11896777 | G4: =F4 -> 0.11896777 | H4: =G4 -> 0.11896777 | I4: =H4 -> 0.11896777 | J4: =I4 -> 0.11896777 | K4: =J4 -> 0.11896777 | L4: =K4 -> 0.11896777 | M4: =L4 -> 0.11896777
B6: Beginning PP&E | F6: =E9 -> 171036 | G6: =F9 -> 235868.63 | H6: =G9 -> 297989.55 | I6: =H9 -> 358468.22 | J6: =I9 -> 417627.73 | K6: =J9 -> 475606.34 | L6: =K9 -> 532304.28 | M6: =L9 -> 587305.86
B7: Capex | F7: =IncState!F17*Calcs!F3 -> 85180.401 | G7: =IncState!G17*Calcs!G3 -> 90181.688 | H7: =IncState!H17*Calcs!H3 -> 95929.815 | I7: =IncState!I17*Calcs!I3 -> 101805.68 | J7: =IncState!J17*Calcs!J3 -> 107662.85 | K7: =IncState!K17*Calcs!K3 -> 113279.77 | L7: =IncState!L17*Calcs!L3 -> 118328.64 | M7: =IncState!M17*Calcs!M3 -> 122332.3
B8: Depreciation | F8: =F6*F4 -> 20347.771 | G8: =G6*G4 -> 28060.765 | H8: =H6*H4 -> 35451.152 | I8: =I6*I4 -> 42646.164 | J8: =J6*J4 -> 49684.239 | K8: =K6*K4 -> 56581.825 | L8: =L6*L4 -> 63327.053 | M8: =M6*M4 -> 69870.468
B9: Ending PP&E | E9: =BalSheet!E23 -> 171036 | F9: =F6+F7-F8 -> 235868.63 | G9: =G6+G7-G8 -> 297989.55 | H9: =H6+H7-H8 -> 358468.22 | I9: =I6+I7-I8 -> 417627.73 | J9: =J6+J7-J8 -> 475606.34 | K9: =K6+K7-K8 -> 532304.28 | L9: =L6+L7-L8 -> 587305.86 | M9: =M6+M7-M8 -> 639767.69
A11: Equity | C11: 44926 | D11: 45291 | E11: 45657 | F11: 46022 | G11: 46387 | H11: 46752 | I11: 47118 | J11: 47483 | K11: =K2 -> 47516 | L11: =L2 -> 47881 | M11: =M2 -> 48246
B12: Share issuance/(repurchases) | F12: =Assumptions!F32 -> 0 | G12: =Assumptions!G32 -> 0 | H12: =Assumptions!H32 -> 0 | I12: =Assumptions!I32 -> 0 | J12: =Assumptions!J32 -> 0 | K12: =Assumptions!K32 -> 0 | L12: =Assumptions!L32 -> 0 | M12: =Assumptions!M32 -> 0
B14: Beginning balance | F14: =E18 -> 325084 | G14: =F18 -> 420745.76 | H14: =G18 -> 530931.44 | I14: =H18 -> 657800.37 | J14: =I18 -> 804533.62 | K14: =J18 -> 975022.21 | L14: =K18 -> 1174045.9 | M14: =L18 -> 1407500.8
B15: Net income | F15: =IncState!F36 -> 104594.1 | G15: =IncState!G36 -> 120474.18 | H15: =IncState!H36 -> 138715.2 | I15: =IncState!I36 -> 160434.35 | J15: =IncState!J36 -> 186407.81 | K15: =IncState!K36 -> 217607.38 | L15: =IncState!L36 -> 255253.59 | M15: =IncState!M36 -> 300884.07
B16: Dividends paid | F16: =IncState!F38 -> 8932.336 | G16: =IncState!G38 -> 10288.495 | H16: =IncState!H38 -> 11846.278 | I16: =IncState!I38 -> 13701.093 | J16: =IncState!J38 -> 15919.227 | K16: =IncState!K38 -> 18583.67 | L16: =IncState!L38 -> 21798.657 | M16: =IncState!M38 -> 25695.499
B17: Share issuance / (repurchase) | F17: =F12 -> 0 | G17: =G12 -> 0 | H17: =H12 -> 0 | I17: =I12 -> 0 | J17: =J12 -> 0 | K17: =K12 -> 0 | L17: =L12 -> 0 | M17: =M12 -> 0
B18: Ending balance | E18: =BalSheet!E40 -> 325084 | F18: =F14+F15-F16-F17 -> 420745.76 | G18: =G14+G15-G16-G17 -> 530931.44 | H18: =H14+H15-H16-H17 -> 657800.37 | I18: =I14+I15-I16-I17 -> 804533.62 | J18: =J14+J15-J16-J17 -> 975022.21 | K18: =K14+K15-K16-K17 -> 1174045.9 | L18: =L14+L15-L16-L17 -> 1407500.8 | M18: =M14+M15-M16-M17 -> 1682689.4
A20: OWC | C20: 44926 | D20: 45291 | E20: 45657 | F20: 46022 | G20: 46387 | H20: 46752 | I20: 47118 | J20: 47483 | K20: =K11 -> 47516 | L20: =L11 -> 47881 | M20: =M11 -> 48246
B21: Operating Cash | E21: =BalSheet!E16 -> 23466 | F21: =BalSheet!F16 -> 26937.203 | G21: =BalSheet!G16 -> 30690.278 | H21: =BalSheet!H16 -> 35337.1 | I21: =BalSheet!I16 -> 40869.96 | J21: =BalSheet!J16 -> 47486.588 | K21: =BalSheet!K16 -> 55434.542 | L21: =BalSheet!L16 -> 65024.753 | M21: =BalSheet!M16 -> 76648.921
B22: =BalSheet!B19 -> Inventories | E22: =BalSheet!E19 -> 0 | F22: =BalSheet!F19 -> 0 | G22: =BalSheet!G19 -> 0 | H22: =BalSheet!H19 -> 0 | I22: =BalSheet!I19 -> 0 | J22: =BalSheet!J19 -> 0 | K22: =BalSheet!K19 -> 0 | L22: =BalSheet!L19 -> 0 | M22: =BalSheet!M19 -> 0
B23: =BalSheet!B18 -> Accounts receivable | E23: =BalSheet!E18 -> 52340 | F23: =BalSheet!F18 -> 60082.384 | G23: =BalSheet!G18 -> 68453.471 | H23: =BalSheet!H18 -> 78818.027 | I23: =BalSheet!I18 -> 91158.855 | J23: =BalSheet!J18 -> 105916.99 | K23: =BalSheet!K18 -> 123644.59 | L23: =BalSheet!L18 -> 145035.18 | M23: =BalSheet!M18 -> 170962.44
B24: Other current assets | E24: =BalSheet!E20 -> 15714 | F24: =BalSheet!F20 -> 18038.49 | G24: =BalSheet!G20 -> 20551.736 | H24: =BalSheet!H20 -> 23663.479 | I24: =BalSheet!I20 -> 27368.556 | J24: =BalSheet!J20 -> 31799.38 | K24: =BalSheet!K20 -> 37121.725 | L24: =BalSheet!L20 -> 43543.807 | M24: =BalSheet!M20 -> 51327.927
B25: Accounts payables | E25: =BalSheet!E32 -> 84086 | F25: =BalSheet!F32 -> 96524.405 | G25: =BalSheet!G32 -> 109972.84 | H25: =BalSheet!H32 -> 126623.86 | I25: =BalSheet!I32 -> 146449.82 | J25: =BalSheet!J32 -> 170159.26 | K25: =BalSheet!K32 -> 198639.26 | L25: =BalSheet!L32 -> 233003.98 | M25: =BalSheet!M32 -> 274657
B26: Other current liabilities | E26: =BalSheet!E33 -> 5036 | F26: =BalSheet!F33 -> 5780.9493 | G26: =BalSheet!G33 -> 6586.3905 | H26: =BalSheet!H33 -> 7583.6375 | I26: =BalSheet!I33 -> 8771.0354 | J26: =BalSheet!J33 -> 10191.019 | K26: =BalSheet!K33 -> 11896.717 | L26: =BalSheet!L33 -> 13954.856 | M26: =BalSheet!M33 -> 16449.5
B28: OWC | E28: =SUM(E21:E24)-SUM(E25:E26) -> 2398 | F28: =SUM(F21:F24)-SUM(F25:F26) -> 2752.7237 | G28: =SUM(G21:G24)-SUM(G25:G26) -> 3136.2519 | H28: =SUM(H21:H24)-SUM(H25:H26) -> 3611.1125 | I28: =SUM(I21:I24)-SUM(I25:I26) -> 4176.5177 | J28: =SUM(J21:J24)-SUM(J25:J26) -> 4852.6736 | K28: =SUM(K21:K24)-SUM(K25:K26) -> 5664.8782 | L28: =SUM(L21:L24)-SUM(L25:L26) -> 6644.9057 | M28: =SUM(M21:M24)-SUM(M25:M26) -> 7832.7841
B29: Change in OWC | F29: =E28-F28 -> -354.72367 | G29: =F28-G28 -> -383.52821 | H29: =G28-H28 -> -474.86063 | I29: =H28-I28 -> -565.40514 | J29: =I28-J28 -> -676.15594 | K29: =J28-K28 -> -812.20465 | L29: =K28-L28 -> -980.0275 | M29: =L28-M28 -> -1187.8784

Sheet Debt
A1: =CoName -> Alphabet Inc. | C1: Hist. | D1: Hist. | E1: Hist. | F1: Proj. | G1: Proj. | H1: Proj. | I1: Proj. | J1: Proj. | K1: Proj. | L1: Proj. | M1: Proj.
A2: Assumptions | C2: 44926 | D2: 45291 | E2: 45657 | F2: 46022 | G2: 46387 | H2: 46752 | I2: 47118 | J2: 47483 | K2: =2030 -> 2030 | L2: =K2+1 -> 2031 | M2: =L2+1 -> 2032
B3: Interest rate on revolver | F3: =Assumptions!F22 -> 0.044 | G3: =Assumptions!G22 -> 0.044 | H3: =Assumptions!H22 -> 0.044 | I3: =Assumptions!I22 -> 0.044 | J3: =Assumptions!J22 -> 0.044 | K3: =Assumptions!K22 -> 0.044 | L3: =Assumptions!L22 -> 0.044 | M3: =Assumptions!M22 -> 0.044
B4: Interest rate on long-term debt | F4: =Assumptions!F23 -> 0.044 | G4: =Assumptions!G23 -> 0.044 | H4: =Assumptions!H23 -> 0.044 | I4: =Assumptions!I23 -> 0.044 | J4: =Assumptions!J23 -> 0.044 | K4: =Assumptions!K23 -> 0.044 | L4: =Assumptions!L23 -> 0.044 | M4: =Assumptions!M23 -> 0.044
B5: Interest rate on cash | F5: =Assumptions!F24 -> 0.046854909 | G5: =Assumptions!G24 -> 0.046854909 | H5: =Assumptions!H24 -> 0.046854909 | I5: =Assumptions!I24 -> 0.046854909 | J5: =Assumptions!J24 -> 0.046854909 | K5: =Assumptions!K24 -> 0.046854909 | L5: =Assumptions!L24 -> 0.046854909 | M5: =Assumptions!M24 -> 0.046854909
B7: Issuance of long-term debt | F7: =Assumptions!F26 -> 0 | G7: =Assumptions!G26 -> 0 | H7: =Assumptions!H26 -> 0 | I7: =Assumptions!I26 -> 0 | J7: =Assumptions!J26 -> 0 | K7: =Assumptions!K26 -> 0 | L7: =Assumptions!L26 -> 0 | M7: =Assumptions!M26 -> 0
B8: Repayment of long-term debt | F8: =Assumptions!F27 -> 0 | G8: =Assumptions!G27 -> 0 | H8: =Assumptions!H27 -> 0 | I8: =Assumptions!I27 -> 0 | J8: =Assumptions!J27 -> 0 | K8: =Assumptions!K27 -> 0 | L8: =Assumptions!L27 -> 0 | M8: =Assumptions!M27 -> 0
A10: Revolver | C10: =C2 -> 44926 | D10: =D2 -> 45291 | E10: =E2 -> 45657 | F10: =F2 -> 46022 | G10: =G2 -> 46387 | H10: =H2 -> 46752 | I10: =I2 -> 47118 | J10: =J2 -> 47483 | ... M10: =M2 -> 2032
B11: Balance | E11: 0 | F11: 0 | G11: 0 | H11: 0 | I11: 0 | J11: 0 | K11: 0 | L11: 0 | M11: 0
B12: Interest rate | F12: 0 | G12: 0 | H12: 0 | I12: 0 | J12: 0 | K12: 0 | L12: 0 | M12: 0
B13: Interest expense | F13: 0 | G13: 0 | H13: 0 | I13: 0 | J13: 0 | K13: 0 | L13: 0 | M13: 0
A15: Long term debt | C15: =C10 -> 44926 | D15: =D10 -> 45291 | E15: =E10 -> 45657 | F15: =F10 -> 46022 | G15: =G10 -> 46387 | H15: =H10 -> 46752 | I15: =I10 -> 47118 | J15: =J10 -> 47483 | ... M15: =M10 -> 2032
B16: Beginning balance | E16: 0 | F16: =E19 -> 10883 | G16: =F19 -> 10883 | H16: =G19 -> 10883 | I16: =H19 -> 10883 | J16: =I19 -> 10883 | K16: =J19 -> 10883 | L16: =K19 -> 10883 | M16: =L19 -> 10883
B17: Issuance | E17: 0 | F17: 0 | G17: 0 | H17: 0 | I17: 0 | J17: 0 | K17: 0 | L17: 0 | M17: 0
B18: Repayment | E18: 0 | F18: 0 | G18: 0 | H18: 0 | I18: 0 | J18: 0 | K18: 0 | L18: 0 | M18: 0
B19: Ending balance | E19: =BalSheet!E36 -> 10883 | F19: =F16+F17-F18 -> 10883 | G19: =G16+G17-G18 -> 10883 | H19: =H16+H17-H18 -> 10883 | I19: =I16+I17-I18 -> 10883 | J19: =J16+J17-J18 -> 10883 | K19: =K16+K17-K18 -> 10883 | L19: =L16+L17-L18 -> 10883 | M19: =M16+M17-M18 -> 10883
B20: Interest rate | E20: 0 | F20: =-F4 -> -0.044 | G20: =-G4 -> -0.044 | H20: =-H4 -> -0.044 | I20: =-I4 -> -0.044 | J20: =-J4 -> -0.044 | K20: =-K4 -> -0.044 | L20: =-L4 -> -0.044 | M20: =-M4 -> -0.044
B21: Interest expense | E21: 0 | F21: =F19*F20 -> -478.852 | G21: =G19*G20 -> -478.852 | H21: =H19*H20 -> -478.852 | I21: =I19*I20 -> -478.852 | J21: =J19*J20 -> -478.852 | K21: =K19*K20 -> -478.852 | L21: =L19*L20 -> -478.852 | M21: =M19*M20 -> -478.852
A23: Debt summary | C23: =C15 -> 44926 | D23: =D15 -> 45291 | E23: =E15 -> 45657 | F23: =F15 -> 46022 | G23: =G15 -> 46387 | H23: =H15 -> 46752 | I23: =I15 -> 47118 | J23: =J15 -> 47483 | ... M23: =M15 -> 2032
B24: Revolver
B25: Total long term debt
B26: Total debt
B28: Total interest expense
A30: Interest income | C30: =C10 -> 44926 | D30: =D10 -> 45291 | E30: =E10 -> 45657 | F30: =F10 -> 46022 | G30: =G10 -> 46387 | H30: =H10 -> 46752 | I30: =I10 -> 47118 | J30: =J10 -> 47483 | ... M30: =M10 -> 2032
B31: Excess Cash | F31: =BalSheet!F17 -> 99636.649 | G31: =BalSheet!G17 -> 144043.18 | H31: =BalSheet!H17 -> 205904.04 | I31: =BalSheet!I17 -> 288084.74 | J31: =BalSheet!J17 -> 394145.3 | K31: =BalSheet!K17 -> 528723.96 | L31: =BalSheet!L17 -> 697829.45 | M31: =BalSheet!M17 -> 909225.77
B32: Interest rate | F32: =F5 -> 0.046854909 | G32: =G5 -> 0.046854909 | H32: =H5 -> 0.046854909 | I32: =I5 -> 0.046854909 | J32: =J5 -> 0.046854909 | K32: =K5 -> 0.046854909 | L32: =L5 -> 0.046854909 | M32: =M5 -> 0.046854909
B33: Interest income | F33: =F31*F32 -> 4668.4661 | G33: =G31*G32 -> 6749.1298 | H33: =H31*H32 -> 9647.615 | I33: =I31*I32 -> 13498.184 | J33: =J31*J32 -> 18467.642 | K33: =K31*K32 -> 24773.313 | L33: =L31*L32 -> 32696.735 | M33: =M31*M32 -> 42601.69

Sheet IncState
A1: =CoName -> Alphabet Inc. | C1: Hist. | D1: Hist. | E1: Hist. | F1: Proj. | G1: Proj. | H1: Proj. | I1: Proj. | J1: Proj. | K1: Proj. | L1: Proj. | M1: Proj.
A2: Assumptions
B4: Revenue growth | F4: =Assumptions!F9 -> 0.1479248 | G4: =Assumptions!G9 -> 0.13932681 | H4: =Assumptions!H9 -> 0.15141023 | I4: =Assumptions!I9 -> 0.15657367 | J4: =Assumptions!J9 -> 0.16189467 | K4: =Assumptions!K9 -> 0.16737261 | L4: =Assumptions!L9 -> 0.17300063 | M4: =Assumptions!M9 -> 0.17876527
B5: Cost of goods sold as % of sales | C5: =Assumptions!C10 -> 0.44620557 | D5: =Assumptions!D10 -> 0.43374952 | E5: =Assumptions!E10 -> 0.41799565 | F5: =Assumptions!F10 -> 0.41799565 | G5: =Assumptions!G10 -> 0.41799565 | H5: =Assumptions!H10 -> 0.41799565 | I5: =Assumptions!I10 -> 0.41799565 | J5: =Assumptions!J10 -> 0.41799565 | ... M5: =Assumptions!M10 -> 0.41799565
B6: R&D % of sales | C6: =Assumptions!C11 -> 0.1396569 | D6: =Assumptions!D11 -> 0.14778102 | E6: =Assumptions!E11 -> 0.14092418 | F6: =Assumptions!F11 -> 0.14092418 | G6: =F6 -> 0.14092418 | H6: =G6 -> 0.14092418 | I6: =H6 -> 0.14092418 | J6: =I6 -> 0.14092418 | K6: =J6 -> 0.14092418 | L6: =K6 -> 0.14092418 | M6: =L6 -> 0.14092418
B7: SG&A % of sales | C7: =Assumptions!C12 -> 0.14952481 | D7: =Assumptions!D12 -> 0.14425135 | E7: =Assumptions!E12 -> 0.1199824 | F7: =Assumptions!F12 -> 0.1199824 | G7: =F7 -> 0.1199824 | H7: =G7 -> 0.1199824 | I7: =H7 -> 0.1199824 | J7: =I7 -> 0.1199824 | K7: =J7 -> 0.1199824 | L7: =K7 -> 0.1199824 | M7: =L7 -> 0.1199824
B8: Amortization amount | C8: =Assumptions!C13 -> 0 | D8: =Assumptions!D13 -> 0 | E8: =Assumptions!E13 -> 0 | F8: =Assumptions!F13 -> 0 | G8: =F8 -> 0 | H8: =G8 -> 0 | I8: =H8 -> 0 | J8: =I8 -> 0 | K8: =J8 -> 0 | L8: =K8 -> 0 | M8: =L8 -> 0
B9: Non recurring items, amount | C9: =Assumptions!C14 -> 0 | D9: =Assumptions!D14 -> 0 | E9: =Assumptions!E14 -> 0 | F9: =Assumptions!F14 -> -1400 | G9: =Assumptions!G14 -> 0 | H9: =Assumptions!H14 -> 0 | I9: =Assumptions!I14 -> 0 | J9: =Assumptions!J14 -> 0 | ... M9: =Assumptions!M14 -> 0
B10: Other income (expense), amt | F10: =Assumptions!F15 -> 0 | G10: =Assumptions!G15 -> 0 | H10: =Assumptions!H15 -> 0 | I10: =Assumptions!I15 -> 0 | J10: =Assumptions!J15 -> 0 | K10: =Assumptions!K15 -> 0 | L10: =Assumptions!L15 -> 0 | M10: =Assumptions!M15 -> 0
B11: Effective tax rate | C11: =1-C36/C33 -> 0.15920817 | D11: =1-D36/D33 -> 0.13950386 | E11: =1-E36/E33 -> 0.16439511 | F11: =Assumptions!F16 -> 0.18039511 | G11: =Assumptions!G16 -> 0.18039511 | H11: =Assumptions!H16 -> 0.18039511 | I11: =Assumptions!I16 -> 0.18039511 | J11: =Assumptions!J16 -> 0.18039511 | K11: =Assumptions!K16 -> 0.18039511 | L11: =Assumptions!L16 -> 0.18039511 | M11: =Assumptions!M16 -> 0.18039511
B12: Dividend Payout Rate | C12: 0 | D12: 0 | E12: =7363/E36 -> 0.073543219 | F12: 0.0854 | G12: =F12 -> 0.0854 | H12: =G12 -> 0.0854 | I12: =H12 -> 0.0854 | J12: =I12 -> 0.0854 | K12: =J12 -> 0.0854 | L12: =K12 -> 0.0854 | M12: =L12 -> 0.0854
B13: Basic WASO | F13: =Assumptions!F18 -> 12314.637 | G13: =Assumptions!G18 -> 12314.637 | H13: =Assumptions!H18 -> 12314.637 | I13: =Assumptions!I18 -> 12314.637 | J13: =Assumptions!J18 -> 12314.637 | K13: =Assumptions!K18 -> 12314.637 | L13: =Assumptions!L18 -> 12314.637 | M13: =Assumptions!M18 -> 12314.637
B14: Diluted WASO | F14: =Assumptions!F19 -> 12452.488 | G14: =Assumptions!G19 -> 12452.488 | H14: =Assumptions!H19 -> 12452.488 | I14: =Assumptions!I19 -> 12452.488 | J14: =Assumptions!J19 -> 12452.488 | K14: =Assumptions!K19 -> 12452.488 | L14: =Assumptions!L19 -> 12452.488 | M14: =Assumptions!M19 -> 12452.488
A16: Income statement | C16: =C39 -> 44926 | D16: =D39 -> 45291 | E16: =E39 -> 45657 | F16: =F39 -> 46022 | G16: =G39 -> 46387 | H16: =H39 -> 46752 | I16: =I39 -> 47118 | J16: =J39 -> 47483 | ... M16: =M39 -> 2032
B17: Revenue | C17: =Revenues!D26 -> 282836 | D17: =Revenues!I26 -> 307394 | E17: =Revenues!N26 -> 350018 | F17: =E17*(1+F4) -> 401794.34 | G17: =F17*(1+G4) -> 457775.07 | H17: =G17*(1+H4) -> 527086.9 | I17: =H17*(1+I4) -> 609614.83 | J17: =I17*(1+J4) -> 708308.22 | K17: =J17*(1+K4) -> 826859.61 | L17: =K17*(1+L4) -> 969906.85 | M17: =L17*(1+M4) -> 1143292.5
B18: COGS | C18: 126203 | D18: 133332 | E18: 146306 | F18: =F17*F5 -> 167948.29 | G18: =G17*G5 -> 191347.98 | H18: =H17*H5 -> 220320.03 | I18: =I17*I5 -> 254816.34 | J18: =J17*J5 -> 296069.75 | K18: =K17*K5 -> 345623.72 | L18: =L17*L5 -> 405416.84 | M18: =M17*M5 -> 477891.29
B19: R&D | C19: 39500 | D19: 45427 | E19: 49326 | F19: =F17*F6 -> 56622.539 | G19: =G17*G6 -> 64511.576 | H19: =H17*H6 -> 74279.289 | I19: =I17*I6 -> 85909.47 | J19: =J17*J6 -> 99817.755 | K19: =K17*K6 -> 116524.51 | L19: =L17*L6 -> 136683.33 | M19: =M17*M6 -> 161117.56
B20: SG&A | C20: =26567+15724 -> 42291 | D20: =27917+16425 -> 44342 | E20: =27808+14188 -> 41996 | F20: =F17*F7 -> 48208.25 | G20: =G17*G7 -> 54924.952 | H20: =H17*H7 -> 63241.151 | I20: =I17*I7 -> 73143.051 | J20: =J17*J7 -> 84984.52 | K20: =K17*K7 -> 99208.601 | L20: =L17*L7 -> 116371.75 | M20: =M17*M7 -> 137174.98
A21: * | B21: EBIT | C21: =C17-SUM(C18:C20) -> 74842 | D21: =D17-SUM(D18:D20) -> 84293 | E21: =E17-SUM(E18:E20) -> 112390 | F21: =F17-SUM(F18:F20) -> 129015.27 | G21: =G17-SUM(G18:G20) -> 146990.55 | H21: =H17-SUM(H18:H20) -> 169246.43 | I21: =I17-SUM(I18:I20) -> 195745.96 | J21: =J17-SUM(J18:J20) -> 227436.19 | ... M21: =M17-SUM(M18:M20) -> 367108.68
B23: Depreciation | C23: 13475 | D23: 11946 | E23: 15311 | F23: =Calcs!F8 -> 20347.771 | G23: =Calcs!G8 -> 28060.765 | H23: =Calcs!H8 -> 35451.152 | I23: =Calcs!I8 -> 42646.164 | J23: =Calcs!J8 -> 49684.239 | K23: =Calcs!K8 -> 56581.825 | L23: =Calcs!L8 -> 63327.053 | M23: =Calcs!M8 -> 69870.468
B24: Amortization | C24: 0 | D24: 0 | E24: 0 | F24: =F8 -> 0 | G24: =G8 -> 0 | H24: =H8 -> 0 | I24: =I8 -> 0 | J24: =J8 -> 0 | K24: =K8 -> 0 | L24: =L8 -> 0 | M24: =M8 -> 0
A25: * | B25: EBITDA | C25: =C21+C23 -> 88317 | D25: =D21+D23 -> 96239 | E25: =E21+E23 -> 127701 | F25: =F21+SUM(F23:F24) -> 149363.04 | G25: =G21+SUM(G23:G24) -> 175051.32 | H25: =H21+SUM(H23:H24) -> 204697.58 | I25: =I21+SUM(I23:I24) -> 238392.13 | J25: =J21+SUM(J23:J24) -> 277120.43 | K25: =K21+SUM(K23:K24) -> 322084.6 | L25: =L21+SUM(L23:L24) -> 374761.98 | M25: =M21+SUM(M23:M24) -> 436979.15
B27: Non-recurring items | C27: 0 | D27: 0 | E27: 0 | F27: =F9 -> -1400 | G27: =G9 -> 0 | H27: =H9 -> 0 | I27: =I9 -> 0 | J27: =J9 -> 0 | K27: =K9 -> 0 | L27: =L9 -> 0 | M27: =M9 -> 0
B28: Other income (expense) | C28: =SUM(-654,-2064,-3455,798,-337,381) -> -5331 | D28: =SUM(-1238,-1215,392,-628,299) -> -2390 | E28: =SUM(-409,-1043,3714,218,-188,919) -> 3211 | F28: =F10 -> 0 | G28: =G10 -> 0 | H28: =H10 -> 0 | I28: =I10 -> 0 | J28: =J10 -> 0 | K28: =K10 -> 0 | L28: =L10 -> 0 | M28: =M10 -> 0
B30: Interest income | C30: 2174 | D30: 3865 | E30: 4482 | F30: =IF(circ=1,Debt!F33,0) -> 0 | G30: =IF(circ=1,Debt!G33,0) -> 0 | H30: =IF(circ=1,Debt!H33,0) -> 0 | I30: =IF(circ=1,Debt!I33,0) -> 0 | J30: =IF(circ=1,Debt!J33,0) -> 0 | K30: =IF(circ=1,Debt!K33,0) -> 0 | L30: =IF(circ=1,Debt!L33,0) -> 0 | M30: =IF(circ=1,Debt!M33,0) -> 0
B31: Interest expense | C31: -357 | D31: -308 | E31: -268 | F31: =IF(circ=1,Debt!F21,0) -> 0 | G31: =IF(circ=1,Debt!G21,0) -> 0 | H31: =IF(circ=1,Debt!H21,0) -> 0 | I31: =IF(circ=1,Debt!I21,0) -> 0 | J31: =IF(circ=1,Debt!J21,0) -> 0 | K31: =IF(circ=1,Debt!K21,0) -> 0 | L31: =IF(circ=1,Debt!L21,0) -> 0 | M31: =IF(circ=1,Debt!M21,0) -> 0
A33: * | B33: Pretax Income | C33: =C21+SUM(C28:C31) -> 71328 | D33: =D21+SUM(D28:D31) -> 85460 | E33: =E21+SUM(E27:E31) -> 119815 | F33: =F21+SUM(F27:F28,F30:F31) -> 127615.27 | G33: =G21+SUM(G27:G28,G30:G31) -> 146990.55 | H33: =H21+SUM(H27:H28,H30:H31) -> 169246.43 | I33: =I21+SUM(I27:I28,I30:I31) -> 195745.96 | J33: =J21+SUM(J27:J28,J30:J31) -> 227436.19 | K33: =K21+SUM(K27:K28,K30:K31) -> 265502.78 | L33: =L21+SUM(L27:L28,L30:L31) -> 311434.93 | M33: =M21+SUM(M27:M28,M30:M31) -> 367108.68
B35: Tax expense | C35: 11356 | D35: 11922 | E35: 19697 | F35: =F33*F11 -> 23021.17 | G35: =G33*G11 -> 26516.377 | H35: =H33*H11 -> 30531.228 | I35: =I33*I11 -> 35311.614 | J35: =J33*J11 -> 41028.376 | K35: =K33*K11 -> 47895.403 | L35: =L33*L11 -> 56181.338 | M35: =M33*M11 -> 66224.61
A36: * | B36: Net income | C36: =C33-C35 -> 59972 | D36: =D33-D35 -> 73538 | E36: =E33-E35 -> 100118 | F36: =F33-F35 -> 104594.1 | G36: =G33-G35 -> 120474.18 | H36: =H33-H35 -> 138715.2 | I36: =I33-I35 -> 160434.35 | J36: =J33-J35 -> 186407.81 | ... M36: =M33-M35 -> 300884.07
B38: Dividends | C38: =C42*C36 -> 0 | D38: =D42*D36 -> 0 | E38: =E42*E36 -> 7363 | F38: =F36*F42 -> 8932.336 | G38: =G36*G42 -> 10288.495 | H38: =H36*H42 -> 11846.278 | I38: =I36*I42 -> 13701.093 | J38: =J36*J42 -> 15919.227 | K38: =K36*K42 -> 18583.67 | L38: =L36*L42 -> 21798.657 | M38: =M36*M42 -> 25695.499
A39: Shareholder information | C39: 44926 | D39: 45291 | E39: 45657 | F39: 46022 | G39: 46387 | H39: 46752 | I39: 47118 | J39: 47483 | K39: =2029+1 -> 2030 | L39: =K39+1 -> 2031 | M39: =L39+1 -> 2032
B40: Basic WASO | C40: =C36/C43 -> 13065.795 | D40: =D36/D43 -> 12592.123 | E40: =E36/E43 -> 12314.637 | F40: =Assumptions!F36 -> 12314.637 | G40: =Assumptions!G36 -> 12314.637 | H40: =Assumptions!H36 -> 12314.637 | I40: =Assumptions!I36 -> 12314.637 | J40: =Assumptions!J36 -> 12314.637 | K40: =Assumptions!K36 -> 12314.637 | L40: =Assumptions!L36 -> 12314.637 | M40: =Assumptions!M36 -> 12314.637
B41: Diluted WASO | C41: =C36/C44 -> 13151.754 | D41: =D36/D44 -> 12678.966 | E41: =E36/E44 -> 12452.488 | F41: =Assumptions!F37 -> 12452.488 | G41: =Assumptions!G37 -> 12452.488 | H41: =Assumptions!H37 -> 12452.488 | I41: =Assumptions!I37 -> 12452.488 | J41: =Assumptions!J37 -> 12452.488 | K41: =Assumptions!K37 -> 12452.488 | L41: =Assumptions!L37 -> 12452.488 | M41: =Assumptions!M37 -> 12452.488
B42: Dividend payout rate | C42: =C12 -> 0 | D42: =D12 -> 0 | E42: =E12 -> 0.073543219 | F42: =F12 -> 0.0854 | G42: =G12 -> 0.0854 | H42: =H12 -> 0.0854 | I42: =I12 -> 0.0854 | J42: =J12 -> 0.0854 | ... M42: =M12 -> 0.0854
B43: Basic earnings per share | C43: 4.59 | D43: 5.84 | E43: 8.13 | F43: =F36/F40 -> 8.4934779 | G43: =G36/G40 -> 9.7830066 | H43: =H36/H40 -> 11.264254 | I43: =I36/I40 -> 13.02794 | J43: =J36/J40 -> 15.137094 | K43: =K36/K40 -> 17.670628 | L43: =L36/L40 -> 20.727658 | M43: =M36/M40 -> 24.433044
A44: * | B44: Diluted earnings per share | C44: 4.56 | D44: 5.8 | E44: 8.04 | F44: =F36/F41 -> 8.3994541 | G44: =G36/G41 -> 9.6747077 | H44: =H36/H41 -> 11.139557 | I44: =I36/I41 -> 12.883719 | J44: =J36/J41 -> 14.969524 | K44: =K36/K41 -> 17.475013 | L44: =L36/L41 -> 20.498201 | M44: =M36/M41 -> 24.162567

Sheet BalSheet
A1: =CoName -> Alphabet Inc. | C1: Hist. | D1: Hist. | E1: Hist. | F1: Proj. | G1: Proj. | H1: Proj. | I1: Proj. | J1: Proj. | K1: Proj. | L1: Proj. | M1: Proj.
A2: Assumptions | C2: 44926 | D2: 45291 | E2: 45657 | F2: 46022 | G2: 46387 | H2: 46752 | I2: 47118 | J2: 47483 | K2: =2030 -> 2030 | L2: =K2+1 -> 2031 | M2: =L2+1 -> 2032
